<?xml version="1.0"?>
<robot xmlns:xacro="http://www.ros.org/wiki/xacro">

<!-- <xacro:include filename="inertial_macros.xacro" /> -->

    
<material name="white">
    <color rgba="1 1 1 1"/>
</material>

<material name="orange">
    <color rgba="1 0.3 0.1 1"/>
</material>

<material name="blue">
    <color rgba="0.2 0.2 1 1"/>
</material>

<material name="black">
    <color rgba="0 0 0 1"/>
</material>

<material name="gray">
    <color rgba="0.663 0.663 0.663 1.0"/>
</material>

<material name="green">
    <color rgba="0 1.0 0 1.0"/>
</material>

<material name="yellow">
    <color rgba="1.0 1.0 0 1.0"/>
</material>

<material name="red">
    <color rgba="1.0 0 0 1.0"/>
</material>

<!-- BASE LINK-->

<link name="base_link">
    
</link>

<!--BASE_FOOTPRINT LINK-->
<joint name="base_footprint_joint" type="fixed">
    <parent link="base_link"/>
    <child link="base_footprint"/>
    <origin xyz="-0 0 0" rpy="0 0 0"/>
        
        
</joint>
<link name="base_footprint">
  
</link>


<!-- CHASSIS LINK-->

  <!-- <joint
    name="chassis_joint"
    type="fixed">
    <origin
      xyz="0 0 0"
      rpy="0 0 0" />
    <parent
      link="base_link" />
    <child
      link="chassis_link" />
    <axis
      xyz="0 0 0" />
  </joint> -->


  <joint
    name="chassis_joint"
    type="revolute">
    <origin
      xyz="0 0 0"
      rpy="0 0 0" />
    <parent
      link="base_link" />
    <child
      link="chassis_link" />
    <axis
      xyz="0 1 0" />
    <dynamics damping="0.5" friction="0.1" />
    <limit effort="1000.0" lower="-1.57" upper="1.57" velocity="10.0"/>
  </joint>



  <link
    name="chassis_link">
    <inertial>
      <origin
        xyz="0.0021178 -0.00024347 0.12856"
        rpy="0 0 0" />
      <mass
        value="0.49806" />
      <inertia
        ixx="0.00048993"
        ixy="6.9843E-08"
        ixz="-4.3059E-07"
        iyy="0.00035439"
        iyz="3.4315E-07"
        izz="0.00020143" />
    </inertial>
    <visual>
      <origin
        xyz="0 0 0"
        rpy="0 0 0" />
      <geometry>
        <mesh
          filename="file://$(find sb_robot)/meshes/chassis_link.STL" />
      </geometry>
      <material
        name="gray">
      </material>
    </visual>
    <collision>
      <origin
        xyz="0 0 0"
        rpy="0 0 0" />
      <geometry>
        <mesh
          filename="file://$(find sb_robot)/meshes/chassis_link.STL" />
      </geometry>
    </collision>
  </link>

<gazebo reference="chassis">
    <material>
        Gazebo/Gray
    </material>
 
</gazebo>



<!-- LEFT WHEEL LINK-->

  <joint
    name="LW_joint"
    type="continuous">
    <origin
      xyz="0 0.0875 0"
      rpy="-${pi/2} 0 0" />
    <parent
      link="chassis_link" />
    <child
      link="LW_link" />
    <axis
      xyz="0 0 1" />
    <dynamics 
      damping="0.5" friction="0.2"/>

  </joint>




<link
    name="LW_link">
    <inertial>
      <origin
        xyz="1.8593E-08 1.3155E-09 0.00062701"
        rpy="0 0 0" />
      <mass
        value="0.030393" />
      <inertia
        ixx="1.2251E-05"
        ixy="1.0839E-12"
        ixz="-5.8809E-13"
        iyy="1.2251E-05"
        iyz="-4.3702E-14"
        izz="2.0609E-05" />
    </inertial>
    <visual>
      <origin
        xyz="0 0 0"
        rpy="0 0 0" />
      <geometry>
        <mesh
          filename="file://$(find sb_robot)/meshes/LW_link.STL" />
      </geometry>
      <material
        name="yellow">
      
      </material>
    </visual>
    <collision>
      <origin
        xyz="0 0 0"
        rpy="0 0 0" />
      <geometry>
        <mesh
          filename="file://$(find sb_robot)/meshes/LW_link.STL" />
      </geometry>
    </collision>
  </link>

<gazebo reference="left_wheel">
    <material>Gazebo/Yellow</material>
<!--     <kp>1000000.0</kp> --> 
<!--    <kd>100.0</kd> -->
<!--     <mu1>0.1</mu1> -->
<!--     <mu2>0.1</mu2> -->
<!--     <fdir1>1 0 0</fdir1> -->
<!--     <maxVel>0.5</maxVel> -->
   <!--  <minDepth>0.001</minDepth> -->
    <mu1>1.0</mu1>
    <mu2>1.0</mu2>
    <kp>1000000.0</kp>
    <kd>100.0</kd>
    <maxVel>0.5</maxVel>
    <minDepth>0.001</minDepth>
</gazebo>


<!-- RIGHT WHEEL LINK-->

  <joint
    name="RW_joint"
    type="continuous">
    <origin
      xyz="0 -0.0875 0"
      rpy="${pi/2} 0 0" />
    <parent
      link="chassis_link" />
    <child
      link="RW_link" />
    <axis
      xyz="0 0 -1" />
    <limit
      effort="10"
      velocity="0.5" />
    <dynamics
      damping="10"
      friction="10" />
  </joint>




<link
    name="RW_link">
    <inertial>
      <origin
        xyz="-1.8593E-08 -1.3155E-09 0.00062701"
        rpy="0 0 0" />
      <mass
        value="0.030393" />
      <inertia
        ixx="1.2251E-05"
        ixy="1.0839E-12"
        ixz="5.8809E-13"
        iyy="1.2251E-05"
        iyz="4.3702E-14"
        izz="2.0609E-05" />
    </inertial>
    <visual>
      <origin
        xyz="0 0 0"
        rpy="0 0 0" />
      <geometry>
        <mesh
          filename="file://$(find sb_robot)/meshes/RW_link.STL" />
      </geometry>
      <material
        name="yellow">
      </material>
    </visual>
    <collision>
      <origin
        xyz="0 0 0"
        rpy="0 0 0" />
      <geometry>
        <mesh
          filename="file://$(find sb_robot)/meshes/RW_link.STL" />
      </geometry>
    </collision>
  </link>

<gazebo reference="right_wheel">
    <material>Gazebo/Yellow</material>
<!--     <kp>1000000.0</kp> --> 
<!--    <kd>100.0</kd> -->
<!--     <mu1>0.1</mu1>
    <mu2>0.1</mu2> -->
<!--     <fdir1>1 0 0</fdir1> -->
<!--     <maxVel>0.5</maxVel> -->
   <!--  <minDepth>0.001</minDepth> -->

  
    <mu1>1.0</mu1>
    <mu2>1.0</mu2>
    <kp>1000000.0</kp>
    <kd>100.0</kd>
    <maxVel>0.5</maxVel>
    <minDepth>0.001</minDepth>
</gazebo>






</robot>