<?xml version="1.0" encoding="utf-8"?>
<!-- This URDF was automatically created by SolidWorks to URDF Exporter! Originally created by Stephen Brawner (brawner@gmail.com) 
     Commit Version: 1.6.0-4-g7f85cfe  Build Version: 1.6.7995.38578
     For more information, please see http://wiki.ros.org/sw_urdf_exporter -->
<robot
  name="sb-bot">
  <link
    name="base_link">
    <inertial>
      <origin
        xyz="0.000233205290793677 1.60098560945669E-06 -0.00134185624212959"
        rpy="0 0 0" />
      <mass
        value="0.000462810146363835" />
      <inertia
        ixx="1.54223233470747E-08"
        ixy="3.27323284605686E-14"
        ixz="1.90031826236237E-15"
        iyy="4.95517271873859E-09"
        iyz="-2.27465190636251E-13"
        izz="2.01685813377348E-08" />
    </inertial>
    <visual>
      <origin
        xyz="0 0 0"
        rpy="0 0 0" />
      <geometry>
        <mesh
          filename="package://sb-bot/meshes/base_link.STL" />
      </geometry>
      <material
        name="">
        <color
          rgba="0.792156862745098 0.819607843137255 0.933333333333333 1" />
      </material>
    </visual>
    <collision>
      <origin
        xyz="0 0 0"
        rpy="0 0 0" />
      <geometry>
        <mesh
          filename="package://sb-bot/meshes/base_link.STL" />
      </geometry>
    </collision>
  </link>
  <link
    name="chassis_link">
    <inertial>
      <origin
        xyz="0.0021178 -0.00024347 0.12856"
        rpy="0 0 0" />
      <mass
        value="0.49806" />
      <inertia
        ixx="0.00048993"
        ixy="6.9843E-08"
        ixz="-4.3059E-07"
        iyy="0.00035439"
        iyz="3.4315E-07"
        izz="0.00020143" />
    </inertial>
    <visual>
      <origin
        xyz="0 0 0"
        rpy="0 0 0" />
      <geometry>
        <mesh
          filename="package://sb-bot/meshes/chassis_link.STL" />
      </geometry>
      <material
        name="">
        <color
          rgba="0.79216 0.81961 0.93333 1" />
      </material>
    </visual>
    <collision>
      <origin
        xyz="0 0 0"
        rpy="0 0 0" />
      <geometry>
        <mesh
          filename="package://sb-bot/meshes/chassis_link.STL" />
      </geometry>
    </collision>
  </link>
  <joint
    name="chassis_joint"
    type="fixed">
    <origin
      xyz="0 0 0"
      rpy="0 0 0" />
    <parent
      link="base_link" />
    <child
      link="chassis_link" />
    <axis
      xyz="0 0 0" />
  </joint>
  <link
    name="LW_link">
    <inertial>
      <origin
        xyz="1.8593E-08 1.3155E-09 0.00062701"
        rpy="0 0 0" />
      <mass
        value="0.030393" />
      <inertia
        ixx="1.2251E-05"
        ixy="1.0839E-12"
        ixz="-5.8809E-13"
        iyy="1.2251E-05"
        iyz="-4.3702E-14"
        izz="2.0609E-05" />
    </inertial>
    <visual>
      <origin
        xyz="0 0 0"
        rpy="0 0 0" />
      <geometry>
        <mesh
          filename="package://sb-bot/meshes/LW_link.STL" />
      </geometry>
      <material
        name="">
        <color
          rgba="1 1 1 1" />
      </material>
    </visual>
    <collision>
      <origin
        xyz="0 0 0"
        rpy="0 0 0" />
      <geometry>
        <mesh
          filename="package://sb-bot/meshes/LW_link.STL" />
      </geometry>
    </collision>
  </link>
  <joint
    name="LW_joint"
    type="continuous">
    <origin
      xyz="0 0.0875 0"
      rpy="-1.5708 0 0" />
    <parent
      link="chassis_link" />
    <child
      link="LW_link" />
    <axis
      xyz="0 0 -1" />
    <limit
      effort="10"
      velocity="0.5" />
    <dynamics
      damping="10"
      friction="10" />
  </joint>
  <link
    name="RW_link">
    <inertial>
      <origin
        xyz="-1.8593E-08 -1.3155E-09 0.00062701"
        rpy="0 0 0" />
      <mass
        value="0.030393" />
      <inertia
        ixx="1.2251E-05"
        ixy="1.0839E-12"
        ixz="5.8809E-13"
        iyy="1.2251E-05"
        iyz="4.3702E-14"
        izz="2.0609E-05" />
    </inertial>
    <visual>
      <origin
        xyz="0 0 0"
        rpy="0 0 0" />
      <geometry>
        <mesh
          filename="package://sb-bot/meshes/RW_link.STL" />
      </geometry>
      <material
        name="">
        <color
          rgba="1 1 1 1" />
      </material>
    </visual>
    <collision>
      <origin
        xyz="0 0 0"
        rpy="0 0 0" />
      <geometry>
        <mesh
          filename="package://sb-bot/meshes/RW_link.STL" />
      </geometry>
    </collision>
  </link>
  <joint
    name="RW_joint"
    type="continuous">
    <origin
      xyz="0 -0.0875 0"
      rpy="1.5708 0 0" />
    <parent
      link="chassis_link" />
    <child
      link="RW_link" />
    <axis
      xyz="0 0 -1" />
    <limit
      effort="10"
      velocity="0.5" />
    <dynamics
      damping="10"
      friction="10" />
  </joint>
  <link
    name="IMU_link">
    <inertial>
      <origin
        xyz="0.00023321 1.601E-06 -0.0013419"
        rpy="0 0 0" />
      <mass
        value="0.00046281" />
      <inertia
        ixx="1.5422E-08"
        ixy="3.2732E-14"
        ixz="1.9003E-15"
        iyy="4.9552E-09"
        iyz="-2.2747E-13"
        izz="2.0169E-08" />
    </inertial>
    <visual>
      <origin
        xyz="0 0 0"
        rpy="0 0 0" />
      <geometry>
        <mesh
          filename="package://sb-bot/meshes/IMU_link.STL" />
      </geometry>
      <material
        name="">
        <color
          rgba="0.79216 0.81961 0.93333 1" />
      </material>
    </visual>
    <collision>
      <origin
        xyz="0 0 0"
        rpy="0 0 0" />
      <geometry>
        <mesh
          filename="package://sb-bot/meshes/IMU_link.STL" />
      </geometry>
    </collision>
  </link>
  <joint
    name="IMU_joint"
    type="fixed">
    <origin
      xyz="0 0 0"
      rpy="0 0 0" />
    <parent
      link="chassis_link" />
    <child
      link="IMU_link" />
    <axis
      xyz="0 0 0" />
  </joint>
  <link
    name="laser_link">
    <inertial>
      <origin
        xyz="-0.0043999 0.01495 -0.0018285"
        rpy="0 0 0" />
      <mass
        value="0.0010395" />
      <inertia
        ixx="1.1109E-07"
        ixy="1.0166E-08"
        ixz="-7.462E-09"
        iyy="2.7229E-08"
        iyz="1.0625E-08"
        izz="1.0422E-07" />
    </inertial>
    <visual>
      <origin
        xyz="0 0 0"
        rpy="0 0 0" />
      <geometry>
        <mesh
          filename="package://sb-bot/meshes/laser_link.STL" />
      </geometry>
      <material
        name="">
        <color
          rgba="0 0.50196 0 1" />
      </material>
    </visual>
    <collision>
      <origin
        xyz="0 0 0"
        rpy="0 0 0" />
      <geometry>
        <mesh
          filename="package://sb-bot/meshes/laser_link.STL" />
      </geometry>
    </collision>
  </link>
  <joint
    name="laser_joint"
    type="fixed">
    <origin
      xyz="0.0275 0 0.0798"
      rpy="0 0 0" />
    <parent
      link="chassis_link" />
    <child
      link="laser_link" />
    <axis
      xyz="0 0 0" />
  </joint>
  <link
    name="camera_link">
    <inertial>
      <origin
        xyz="-0.0041689 0.00043026 -0.0083913"
        rpy="0 0 0" />
      <mass
        value="0.003121" />
      <inertia
        ixx="4.4931E-07"
        ixy="2.6755E-10"
        ixz="2.4863E-10"
        iyy="3.5954E-07"
        iyz="1.5598E-09"
        izz="9.6364E-08" />
    </inertial>
    <visual>
      <origin
        xyz="0 0 0"
        rpy="0 0 0" />
      <geometry>
        <mesh
          filename="package://sb-bot/meshes/camera_link.STL" />
      </geometry>
      <material
        name="">
        <color
          rgba="0.79216 0.81961 0.93333 1" />
      </material>
    </visual>
    <collision>
      <origin
        xyz="0 0 0"
        rpy="0 0 0" />
      <geometry>
        <mesh
          filename="package://sb-bot/meshes/camera_link.STL" />
      </geometry>
    </collision>
  </link>
  <joint
    name="camera_joint"
    type="fixed">
    <origin
      xyz="0.0297 -0.00050584 0.04977"
      rpy="0 0 0" />
    <parent
      link="chassis_link" />
    <child
      link="camera_link" />
    <axis
      xyz="0 0 0" />
  </joint>
</robot>